Workbook

Sheet Dashboard
A1: FUND AUTOMATION — EXECUTIVE DASHBOARD
A3: KEY METRICS | D3: Per Unit
B4: Gross Annual Revenue | C4: ='Inputs & Assumptions'!C4*'Inputs & Assumptions'!C5*12 -> 540000 | D4: =IF('Inputs & Assumptions'!C4>0,C4/'Inputs & Assumptions'!C4,0) -> 18000
B5: Total Baseline Operating Costs | C5: ='Savings Analysis'!C30 -> 421785 | D5: =IF('Inputs & Assumptions'!C4>0,C5/'Inputs & Assumptions'!C4,0) -> 14059.5
B6: Baseline NOI (before automation) | C6: =C4-C5 -> 118215 | D6: =IF('Inputs & Assumptions'!C4>0,C6/'Inputs & Assumptions'!C4,0) -> 3940.5
B7: Baseline Operating Expense Ratio | C7: =IF(C4>0,C5/C4,0) -> 0.78108333
B9: Total Automation Upfront Investment | C9: ='Automation Costs'!D17 -> 28500 | D9: =IF('Inputs & Assumptions'!C4>0,C9/'Inputs & Assumptions'!C4,0) -> 950
B10: Total Automation Annual Cost | C10: ='Automation Costs'!E17 -> 13320 | D10: =IF('Inputs & Assumptions'!C4>0,C10/'Inputs & Assumptions'!C4,0) -> 444
B11: Total Annual Savings from Automation | C11: ='Savings Analysis'!D50 -> 52926.75 | D11: =IF('Inputs & Assumptions'!C4>0,C11/'Inputs & Assumptions'!C4,0) -> 1764.225
B12: Net Annual Benefit (Savings - Auto Cost) | C12: =C11-C10 -> 39606.75 | D12: =IF('Inputs & Assumptions'!C4>0,C12/'Inputs & Assumptions'!C4,0) -> 1320.225
B13: New Operating Costs (Baseline - Savings + Auto Cost) | C13: =C5-C11+C10 -> 382178.25 | D13: =IF('Inputs & Assumptions'!C4>0,C13/'Inputs & Assumptions'!C4,0) -> 12739.275
B14: New NOI (after automation) | C14: =C4-C13 -> 157821.75 | D14: =IF('Inputs & Assumptions'!C4>0,C14/'Inputs & Assumptions'!C4,0) -> 5260.725
B15: NOI Improvement | C15: =C14-C6 -> 39606.75 | D15: =IF('Inputs & Assumptions'!C4>0,C15/'Inputs & Assumptions'!C4,0) -> 1320.225
B16: New Operating Expense Ratio | C16: =IF(C4>0,C13/C4,0) -> 0.7077375
B17: Payback Period (months) | C17: =IF(C12>0,ROUND(C9/(C12/12),1),0) -> 8.6
B18: ROI on Automation (Year 1) | C18: =IF(C9+C10>0,(C11-(C9+C10))/(C9+C10),0) -> 0.26558465
B19: ROI on Automation (Year 2+) | C19: =IF(C10>0,(C11-C10)/C10,0) -> 2.9734797
A22: SCENARIO ANALYSIS — BY PORTFOLIO SIZE
B24: Units → | C24: 10 | D24: 25 | E24: 50 | F24: 100 | G24: 200
B25: Gross Revenue | C25: =C24*'Inputs & Assumptions'!C5*12 -> 180000 | D25: =D24*'Inputs & Assumptions'!C5*12 -> 450000 | E25: =E24*'Inputs & Assumptions'!C5*12 -> 900000 | F25: =F24*'Inputs & Assumptions'!C5*12 -> 1800000 | G25: =G24*'Inputs & Assumptions'!C5*12 -> 3600000
B26: Baseline Op Costs (est.) | C26: =C24*('Savings Analysis'!C30/'Inputs & Assumptions'!C4) -> 140595 | D26: =D24*('Savings Analysis'!C30/'Inputs & Assumptions'!C4) -> 351487.5 | E26: =E24*('Savings Analysis'!C30/'Inputs & Assumptions'!C4) -> 702975 | F26: =F24*('Savings Analysis'!C30/'Inputs & Assumptions'!C4) -> 1405950 | G26: =G24*('Savings Analysis'!C30/'Inputs & Assumptions'!C4) -> 2811900
B27: Automation Annual Cost (est.) | C27: =C24*('Automation Costs'!E17/'Inputs & Assumptions'!C4) -> 4440 | D27: =D24*('Automation Costs'!E17/'Inputs & Assumptions'!C4) -> 11100 | E27: =E24*('Automation Costs'!E17/'Inputs & Assumptions'!C4) -> 22200 | F27: =F24*('Automation Costs'!E17/'Inputs & Assumptions'!C4) -> 44400 | G27: =G24*('Automation Costs'!E17/'Inputs & Assumptions'!C4) -> 88800
B28: Automation Upfront (est.) | C28: =C24*('Automation Costs'!D17/'Inputs & Assumptions'!C4) -> 9500 | D28: =D24*('Automation Costs'!D17/'Inputs & Assumptions'!C4) -> 23750 | E28: =E24*('Automation Costs'!D17/'Inputs & Assumptions'!C4) -> 47500 | F28: =F24*('Automation Costs'!D17/'Inputs & Assumptions'!C4) -> 95000 | G28: =G24*('Automation Costs'!D17/'Inputs & Assumptions'!C4) -> 190000
B29: Est. Annual Savings | C29: =C24*('Savings Analysis'!D50/'Inputs & Assumptions'!C4) -> 17642.25 | D29: =D24*('Savings Analysis'!D50/'Inputs & Assumptions'!C4) -> 44105.625 | E29: =E24*('Savings Analysis'!D50/'Inputs & Assumptions'!C4) -> 88211.25 | F29: =F24*('Savings Analysis'!D50/'Inputs & Assumptions'!C4) -> 176422.5 | G29: =G24*('Savings Analysis'!D50/'Inputs & Assumptions'!C4) -> 352845
B30: Net Annual Benefit | C30: =C29-C27 -> 13202.25 | D30: =D29-D27 -> 33005.625 | E30: =E29-E27 -> 66011.25 | F30: =F29-F27 -> 132022.5 | G30: =G29-G27 -> 264045
B31: Payback (months) | C31: =IF(C30>0,ROUND(C28/(C30/12),1),0) -> 8.6 | D31: =IF(D30>0,ROUND(D28/(D30/12),1),0) -> 8.6 | E31: =IF(E30>0,ROUND(E28/(E30/12),1),0) -> 8.6 | F31: =IF(F30>0,ROUND(F28/(F30/12),1),0) -> 8.6 | G31: =IF(G30>0,ROUND(G28/(G30/12),1),0) -> 8.6
B32: Op Expense Ratio | C32: =IF(C25>0,(C26-C29+C27)/C25,0) -> 0.7077375 | D32: =IF(D25>0,(D26-D29+D27)/D25,0) -> 0.7077375 | E32: =IF(E25>0,(E26-E29+E27)/E25,0) -> 0.7077375 | F32: =IF(F25>0,(F26-F29+F27)/F25,0) -> 0.7077375 | G32: =IF(G25>0,(G26-G29+G27)/G25,0) -> 0.7077375

Sheet Inputs & Assumptions
A1: REAL ESTATE FUND — AUTOMATION COST MODEL
A3: PORTFOLIO INPUTS
B4: Total number of units | C4: 30 | D4: ← | E4: Change to model different portfolio sizes
B5: Average monthly rent per unit | C5: 1500 | D5: ← | E5: Market rate
B6: Average unit square footage | C6: 950 | D6: ← | E6: Used for pest/cleaning estimates
B7: Number of properties (buildings) | C7: 5 | D7: ← | E7: Distinct locations
B8: Current vacancy rate | C8: 0.07 | D8: ← | E8: Current baseline
B9: Average tenant turnover rate (per year) | C9: 0.35 | D9: ← | E9: % of units that turn over annually
B10: Average cost per tenant turn | C10: 2500 | D10: ← | E10: Cleaning, paint, minor repairs
B11: Property manager hourly rate | C11: 30 | D11: ← | E11: Fully loaded labor cost
B12: Hours/week on manual operational tasks | C12: 20 | D12: ← | E12: Before automation
B13: Annual insurance premium per unit | C13: 1200 | D13: ← | E13: Property insurance
B14: Annual property tax per unit | C14: 2400 | D14: ← | E14: Local property tax
A16: MAINTENANCE & REPAIR INPUTS
B17: Maintenance calls per unit per year | C17: 8 | E17: Industry avg 6-12
B18: Average cost per maintenance call | C18: 185 | E18: Blended across types
B19: Emergency calls (% of total) | C19: 0.15 | E19: After-hours premium
B20: Emergency call premium multiplier | C20: 1.75 | E20: After-hours markup
B21: Annual HVAC service cost per unit | C21: 250 | E21: Preventive maintenance
B22: Plumbing incidents per unit per year | C22: 1.5 | E22: Avg
B23: Avg plumbing repair cost | C23: 275
B24: Electrical issues per unit per year | C24: 0.5
B25: Avg electrical repair cost | C25: 200
A27: LOCKOUT & ACCESS INPUTS
B28: Lockout incidents per unit per year | C28: 2 | E28: Tenant lockouts
B29: Locksmith call cost | C29: 125 | E29: Including travel
B30: Re-keying cost per unit at turnover | C30: 85 | E30: Per lock change
B31: Number of locks per unit | C31: 2 | E31: Front + back/storage
B32: Contractor/inspector access visits per unit/yr | C32: 6 | E32: Includes showings
B33: Coordination time per access visit (minutes) | C33: 20 | E33: Scheduling, meeting, etc
A35: APPLIANCE & EQUIPMENT INPUTS
B36: Appliance replacements per year (portfolio-wide) | C36: 5 | E36: Fridges, dishwashers, etc
B37: Average appliance cost (one-off purchase) | C37: 900 | E37: Retail price
B38: Bulk discount when standardized | C38: 0.2 | E38: Volume savings
B39: Average appliance lifespan (years) | C39: 12
B40: Water heater replacements per year | C40: 2 | E40: Portfolio-wide
B41: Average water heater cost | C41: 1200
B42: HVAC unit replacements per year | C42: 1 | E42: Portfolio-wide
B43: Average HVAC replacement cost | C43: 5500
A45: ADDITIONAL OPERATIONAL COST INPUTS
...

Sheet Automation Costs
A1: AUTOMATION INVESTMENT — TOGGLE ON/OFF
B3: Automation Item | C3: Toggle (1=On) | D3: Upfront Cost | E3: Annual Cost | F3: Per-Unit Annual
B4: 1. PM Software (AppFolio/Buildium) | C4: 1 | D4: =0 -> 0 | E4: =IF(C4=1,MAX('Inputs & Assumptions'!C4*1.4*12,280*12),0) -> 3360 | F4: =IF('Inputs & Assumptions'!C4>0,E4/'Inputs & Assumptions'!C4,0) -> 112
B5: 2. Smart Locks (keyless entry) | C5: 1 | D5: =IF(C5=1,'Inputs & Assumptions'!C4*'Inputs & Assumptions'!C31*250,0) -> 15000 | E5: =IF(C5=1,'Inputs & Assumptions'!C4*20,0) -> 600 | F5: =IF('Inputs & Assumptions'!C4>0,E5/'Inputs & Assumptions'!C4,0) -> 20
B6: 3. Maintenance Auto-Dispatch (Property Meld) | C6: 1 | D6: =0 -> 0 | E6: =IF(C6=1,'Inputs & Assumptions'!C4*3.5*12,0) -> 1260 | F6: =IF('Inputs & Assumptions'!C4>0,E6/'Inputs & Assumptions'!C4,0) -> 42
B7: 4. Appliance Standardization & Bulk Purchasing | C7: 1 | D7: =0 -> 0 | E7: =IF(C7=1,150*12,0) -> 1800 | F7: =IF('Inputs & Assumptions'!C4>0,E7/'Inputs & Assumptions'!C4,0) -> 60
B8: 5. Vacancy Reduction (faster turns, auto-listing) | C8: 1 | D8: =0 -> 0 | E8: =IF(C8=1,'Inputs & Assumptions'!C4*2*12,0) -> 720 | F8: =IF('Inputs & Assumptions'!C4>0,E8/'Inputs & Assumptions'!C4,0) -> 24
B9: 6. Online Rent Collection & Auto-ACH | C9: 1 | D9: =0 -> 0 | E9: =IF(C9=1,0,0) -> 0 | F9: =IF('Inputs & Assumptions'!C4>0,E9/'Inputs & Assumptions'!C4,0) -> 0
B10: 7. E-Signature & Lease Automation (DocuSign) | C10: 1 | D10: =0 -> 0 | E10: =IF(C10=1,25*12,0) -> 300 | F10: =IF('Inputs & Assumptions'!C4>0,E10/'Inputs & Assumptions'!C4,0) -> 10
B11: 8. Tenant Communication Portal / App | C11: 1 | D11: =0 -> 0 | E11: =IF(C11=1,'Inputs & Assumptions'!C4*1*12,0) -> 360 | F11: =IF('Inputs & Assumptions'!C4>0,E11/'Inputs & Assumptions'!C4,0) -> 12
B12: 9. Security Cameras & Leak/Smoke Sensors | C12: 1 | D12: =IF(C12=1,'Inputs & Assumptions'!C7*1500+'Inputs & Assumptions'!C4*200,0) -> 13500 | E12: =IF(C12=1,('Inputs & Assumptions'!C7*30+'Inputs & Assumptions'!C4*5)*12,0) -> 3600 | F12: =IF('Inputs & Assumptions'!C4>0,E12/'Inputs & Assumptions'!C4,0) -> 120
B13: 10. Preventive Maintenance Scheduling Software | C13: 1 | D13: =0 -> 0 | E13: =IF(C13=1,'Inputs & Assumptions'!C4*2*12,0) -> 720 | F13: =IF('Inputs & Assumptions'!C4>0,E13/'Inputs & Assumptions'!C4,0) -> 24
B14: 11. Accounting Automation (QuickBooks integration) | C14: 1 | D14: =0 -> 0 | E14: =IF(C14=1,50*12,0) -> 600 | F14: =IF('Inputs & Assumptions'!C4>0,E14/'Inputs & Assumptions'!C4,0) -> 20
B15: 12. Tenant Screening Automation (TransUnion/RentPrep) | C15: 1 | D15: =0 -> 0 | E15: =IF(C15=1,0,0) -> 0 | F15: =0 -> 0
B17: TOTAL AUTOMATION INVESTMENT | D17: =SUM(D4:D15) -> 28500 | E17: =SUM(E4:E15) -> 13320 | F17: =SUM(F4:F15) -> 444

Sheet Savings Analysis
A1: BASELINE COSTS (BEFORE AUTOMATION)
B3: Cost Category | C3: Annual Cost | D3: Per Unit/Year | E3: % of Revenue
B4: Maintenance (routine calls) | C4: ='Inputs & Assumptions'!C4*'Inputs & Assumptions'!C17*'Inputs & Assumptions'!C18 -> 44400 | D4: =IF('Inputs & Assumptions'!C4>0,C4/'Inputs & Assumptions'!C4,0) -> 1480 | E4: =IF('Inputs & Assumptions'!C4*'Inputs & Assumptions'!C5*12>0,C4/('Inputs & Assumptions'!C4*'Inputs & Assumptions'!C5*12),0) -> 0.082222222
B5: Emergency maintenance premium | C5: ='Inputs & Assumptions'!C4*'Inputs & Assumptions'!C17*'Inputs & Assumptions'!C19*'Inputs & Assumptions'!C18*('Inputs & Assumptions'!C20-1) -> 4995 | D5: =IF('Inputs & Assumptions'!C4>0,C5/'Inputs & Assumptions'!C4,0) -> 166.5 | E5: =IF('Inputs & Assumptions'!C4*'Inputs & Assumptions'!C5*12>0,C5/('Inputs & Assumptions'!C4*'Inputs & Assumptions'!C5*12),0) -> 0.00925
B6: HVAC preventive service | C6: ='Inputs & Assumptions'!C4*'Inputs & Assumptions'!C21 -> 7500 | D6: =IF('Inputs & Assumptions'!C4>0,C6/'Inputs & Assumptions'!C4,0) -> 250 | E6: =IF('Inputs & Assumptions'!C4*'Inputs & Assumptions'!C5*12>0,C6/('Inputs & Assumptions'!C4*'Inputs & Assumptions'!C5*12),0) -> 0.013888889
B7: Plumbing repairs | C7: ='Inputs & Assumptions'!C4*'Inputs & Assumptions'!C22*'Inputs & Assumptions'!C23 -> 12375 | D7: =IF('Inputs & Assumptions'!C4>0,C7/'Inputs & Assumptions'!C4,0) -> 412.5 | E7: =IF('Inputs & Assumptions'!C4*'Inputs & Assumptions'!C5*12>0,C7/('Inputs & Assumptions'!C4*'Inputs & Assumptions'!C5*12),0) -> 0.022916667
B8: Electrical repairs | C8: ='Inputs & Assumptions'!C4*'Inputs & Assumptions'!C24*'Inputs & Assumptions'!C25 -> 3000 | D8: =IF('Inputs & Assumptions'!C4>0,C8/'Inputs & Assumptions'!C4,0) -> 100 | E8: =IF('Inputs & Assumptions'!C4*'Inputs & Assumptions'!C5*12>0,C8/('Inputs & Assumptions'!C4*'Inputs & Assumptions'!C5*12),0) -> 0.0055555556
B9: Lockout / locksmith costs | C9: ='Inputs & Assumptions'!C4*'Inputs & Assumptions'!C28*'Inputs & Assumptions'!C29 -> 7500 | D9: =IF('Inputs & Assumptions'!C4>0,C9/'Inputs & Assumptions'!C4,0) -> 250 | E9: =IF('Inputs & Assumptions'!C4*'Inputs & Assumptions'!C5*12>0,C9/('Inputs & Assumptions'!C4*'Inputs & Assumptions'!C5*12),0) -> 0.013888889
B10: Re-keying at turnover | C10: ='Inputs & Assumptions'!C4*'Inputs & Assumptions'!C9*'Inputs & Assumptions'!C30*'Inputs & Assumptions'!C31 -> 1785 | D10: =IF('Inputs & Assumptions'!C4>0,C10/'Inputs & Assumptions'!C4,0) -> 59.5 | E10: =IF('Inputs & Assumptions'!C4*'Inputs & Assumptions'!C5*12>0,C10/('Inputs & Assumptions'!C4*'Inputs & Assumptions'!C5*12),0) -> 0.0033055556
B11: Contractor access coordination (labor) | C11: ='Inputs & Assumptions'!C4*'Inputs & Assumptions'!C32*'Inputs & Assumptions'!C33/60*'Inputs & Assumptions'!C11 -> 1800 | D11: =IF('Inputs & Assumptions'!C4>0,C11/'Inputs & Assumptions'!C4,0) -> 60 | E11: =IF('Inputs & Assumptions'!C4*'Inputs & Assumptions'!C5*12>0,C11/('Inputs & Assumptions'!C4*'Inputs & Assumptions'!C5*12),0) -> 0.0033333333
B12: Appliance replacements | C12: ='Inputs & Assumptions'!C36*'Inputs & Assumptions'!C37 -> 4500 | D12: =IF('Inputs & Assumptions'!C4>0,C12/'Inputs & Assumptions'!C4,0) -> 150 | E12: =IF('Inputs & Assumptions'!C4*'Inputs & Assumptions'!C5*12>0,C12/('Inputs & Assumptions'!C4*'Inputs & Assumptions'!C5*12),0) -> 0.0083333333
B13: Water heater replacements | C13: ='Inputs & Assumptions'!C40*'Inputs & Assumptions'!C41 -> 2400 | D13: =IF('Inputs & Assumptions'!C4>0,C13/'Inputs & Assumptions'!C4,0) -> 80 | E13: =IF('Inputs & Assumptions'!C4*'Inputs & Assumptions'!C5*12>0,C13/('Inputs & Assumptions'!C4*'Inputs & Assumptions'!C5*12),0) -> 0.0044444444
B14: HVAC replacements | C14: ='Inputs & Assumptions'!C42*'Inputs & Assumptions'!C43 -> 5500 | D14: =IF('Inputs & Assumptions'!C4>0,C14/'Inputs & Assumptions'!C4,0) -> 183.33333 | E14: =IF('Inputs & Assumptions'!C4*'Inputs & Assumptions'!C5*12>0,C14/('Inputs & Assumptions'!C4*'Inputs & Assumptions'!C5*12),0) -> 0.010185185
B15: Tenant turnover costs | C15: ='Inputs & Assumptions'!C4*'Inputs & Assumptions'!C9*'Inputs & Assumptions'!C10 -> 26250 | D15: =IF('Inputs & Assumptions'!C4>0,C15/'Inputs & Assumptions'!C4,0) -> 875 | E15: =IF('Inputs & Assumptions'!C4*'Inputs & Assumptions'!C5*12>0,C15/('Inputs & Assumptions'!C4*'Inputs & Assumptions'!C5*12),0) -> 0.048611111
B16: Vacancy loss | C16: ='Inputs & Assumptions'!C4*'Inputs & Assumptions'!C5*12*'Inputs & Assumptions'!C8 -> 37800 | D16: =IF('Inputs & Assumptions'!C4>0,C16/'Inputs & Assumptions'!C4,0) -> 1260 | E16: =IF('Inputs & Assumptions'!C4*'Inputs & Assumptions'!C5*12>0,C16/('Inputs & Assumptions'!C4*'Inputs & Assumptions'!C5*12),0) -> 0.07
B17: PM labor (manual tasks) | C17: ='Inputs & Assumptions'!C12*'Inputs & Assumptions'!C11*52 -> 31200 | D17: =IF('Inputs & Assumptions'!C4>0,C17/'Inputs & Assumptions'!C4,0) -> 1040 | E17: =IF('Inputs & Assumptions'!C4*'Inputs & Assumptions'!C5*12>0,C17/('Inputs & Assumptions'!C4*'Inputs & Assumptions'!C5*12),0) -> 0.057777778
B18: Pest control | C18: ='Inputs & Assumptions'!C4*'Inputs & Assumptions'!C46*'Inputs & Assumptions'!C47 -> 5700 | D18: =IF('Inputs & Assumptions'!C4>0,C18/'Inputs & Assumptions'!C4,0) -> 190 | E18: =IF('Inputs & Assumptions'!C4*'Inputs & Assumptions'!C5*12>0,C18/('Inputs & Assumptions'!C4*'Inputs & Assumptions'!C5*12),0) -> 0.010555556
B19: Common area cleaning | C19: ='Inputs & Assumptions'!C7*'Inputs & Assumptions'!C48*12 -> 21000 | D19: =IF('Inputs & Assumptions'!C4>0,C19/'Inputs & Assumptions'!C4,0) -> 700 | E19: =IF('Inputs & Assumptions'!C4*'Inputs & Assumptions'!C5*12>0,C19/('Inputs & Assumptions'!C4*'Inputs & Assumptions'!C5*12),0) -> 0.038888889
B20: Landscaping / snow removal | C20: ='Inputs & Assumptions'!C7*'Inputs & Assumptions'!C49*12 -> 24000 | D20: =IF('Inputs & Assumptions'!C4>0,C20/'Inputs & Assumptions'!C4,0) -> 800 | E20: =IF('Inputs & Assumptions'!C4*'Inputs & Assumptions'!C5*12>0,C20/('Inputs & Assumptions'!C4*'Inputs & Assumptions'!C5*12),0) -> 0.044444444
B21: Legal / eviction | C21: ='Inputs & Assumptions'!C50*'Inputs & Assumptions'!C51 -> 3500 | D21: =IF('Inputs & Assumptions'!C4>0,C21/'Inputs & Assumptions'!C4,0) -> 116.66667 | E21: =IF('Inputs & Assumptions'!C4*'Inputs & Assumptions'!C5*12>0,C21/('Inputs & Assumptions'!C4*'Inputs & Assumptions'!C5*12),0) -> 0.0064814815
B22: Lease renewal admin labor | C22: ='Inputs & Assumptions'!C4*'Inputs & Assumptions'!C9*'Inputs & Assumptions'!C53*'Inputs & Assumptions'!C11 -> 630 | D22: =IF('Inputs & Assumptions'!C4>0,C22/'Inputs & Assumptions'!C4,0) -> 21 | E22: =IF('Inputs & Assumptions'!C4*'Inputs & Assumptions'!C5*12>0,C22/('Inputs & Assumptions'!C4*'Inputs & Assumptions'!C5*12),0) -> 0.0011666667
B23: Marketing per vacancy | C23: ='Inputs & Assumptions'!C4*'Inputs & Assumptions'!C9*'Inputs & Assumptions'!C54 -> 2100 | D23: =IF('Inputs & Assumptions'!C4>0,C23/'Inputs & Assumptions'!C4,0) -> 70 | E23: =IF('Inputs & Assumptions'!C4*'Inputs & Assumptions'!C5*12>0,C23/('Inputs & Assumptions'!C4*'Inputs & Assumptions'!C5*12),0) -> 0.0038888889
B24: Annual inspections | C24: ='Inputs & Assumptions'!C4*'Inputs & Assumptions'!C55 -> 2250 | D24: =IF('Inputs & Assumptions'!C4>0,C24/'Inputs & Assumptions'!C4,0) -> 75 | E24: =IF('Inputs & Assumptions'!C4*'Inputs & Assumptions'!C5*12>0,C24/('Inputs & Assumptions'!C4*'Inputs & Assumptions'!C5*12),0) -> 0.0041666667
B25: Trash / waste management | C25: ='Inputs & Assumptions'!C7*'Inputs & Assumptions'!C56*12 -> 15000 | D25: =IF('Inputs & Assumptions'!C4>0,C25/'Inputs & Assumptions'!C4,0) -> 500 | E25: =IF('Inputs & Assumptions'!C4*'Inputs & Assumptions'!C5*12>0,C25/('Inputs & Assumptions'!C4*'Inputs & Assumptions'!C5*12),0) -> 0.027777778
B26: Water / sewer (owner-paid) | C26: ='Inputs & Assumptions'!C4*'Inputs & Assumptions'!C57*12 -> 21600 | D26: =IF('Inputs & Assumptions'!C4>0,C26/'Inputs & Assumptions'!C4,0) -> 720 | E26: =IF('Inputs & Assumptions'!C4*'Inputs & Assumptions'!C5*12>0,C26/('Inputs & Assumptions'!C4*'Inputs & Assumptions'!C5*12),0) -> 0.04
B27: Insurance | C27: ='Inputs & Assumptions'!C4*'Inputs & Assumptions'!C13 -> 36000 | D27: =IF('Inputs & Assumptions'!C4>0,C27/'Inputs & Assumptions'!C4,0) -> 1200 | E27: =IF('Inputs & Assumptions'!C4*'Inputs & Assumptions'!C5*12>0,C27/('Inputs & Assumptions'!C4*'Inputs & Assumptions'!C5*12),0) -> 0.066666667
B28: Property tax | C28: ='Inputs & Assumptions'!C4*'Inputs & Assumptions'!C14 -> 72000 | D28: =IF('Inputs & Assumptions'!C4>0,C28/'Inputs & Assumptions'!C4,0) -> 2400 | E28: =IF('Inputs & Assumptions'!C4*'Inputs & Assumptions'!C5*12>0,C28/('Inputs & Assumptions'!C4*'Inputs & Assumptions'!C5*12),0) -> 0.13333333
B29: Cap-ex reserve | C29: ='Inputs & Assumptions'!C4*'Inputs & Assumptions'!C5*12*'Inputs & Assumptions'!C58 -> 27000 | D29: =IF('Inputs & Assumptions'!C4>0,C29/'Inputs & Assumptions'!C4,0) -> 900 | E29: =IF('Inputs & Assumptions'!C4*'Inputs & Assumptions'!C5*12>0,C29/('Inputs & Assumptions'!C4*'Inputs & Assumptions'!C5*12),0) -> 0.05
B30: TOTAL BASELINE OPERATING COSTS | C30: =SUM(C4:C29) -> 421785 | D30: =IF('Inputs & Assumptions'!C4>0,C30/'Inputs & Assumptions'!C4,0) -> 14059.5 | E30: =IF('Inputs & Assumptions'!C4*'Inputs & Assumptions'!C5*12>0,C30/('Inputs & Assumptions'!C4*'Inputs & Assumptions'!C5*12),0) -> 0.78108333
A33: ESTIMATED SAVINGS FROM AUTOMATION
B35: Savings Category | C35: Savings % | D35: Annual Savings | E35: Enabled?
B36: Maintenance dispatch efficiency | C36: 0.25 | D36: =IF('Automation Costs'!C6=1,C36*(C4+C5),0) -> 12348.75 | E36: =IF('Automation Costs'!C6=1,"ON","OFF") -> ON
B37: HVAC preventive - fewer breakdowns | C37: 0.3 | D37: =IF('Automation Costs'!C13=1,C37*(C6),0) -> 2250 | E37: =IF('Automation Costs'!C13=1,"ON","OFF") -> ON
B38: Plumbing early detection (sensors) | C38: 0.15 | D38: =IF('Automation Costs'!C12=1,C38*(C7),0) -> 1856.25 | E38: =IF('Automation Costs'!C12=1,"ON","OFF") -> ON
B39: Lockout elimination (smart locks) | C39: 0.9 | D39: =IF('Automation Costs'!C5=1,C39*(C9),0) -> 6750 | E39: =IF('Automation Costs'!C5=1,"ON","OFF") -> ON
B40: Re-keying elimination | C40: 0.95 | D40: =IF('Automation Costs'!C5=1,C40*(C10),0) -> 1695.75 | E40: =IF('Automation Costs'!C5=1,"ON","OFF") -> ON
B41: Access coordination savings | C41: 0.8 | D41: =IF('Automation Costs'!C5=1,C41*(C11),0) -> 1440 | E41: =IF('Automation Costs'!C5=1,"ON","OFF") -> ON
B42: Appliance bulk purchasing savings | C42: 0.2 | D42: =IF('Automation Costs'!C7=1,C42*(C12),0) -> 900 | E42: =IF('Automation Costs'!C7=1,"ON","OFF") -> ON
B43: Vacancy reduction (faster turns) | C43: 0.15 | D43: =IF('Automation Costs'!C8=1,C43*(C16),0) -> 5670 | E43: =IF('Automation Costs'!C8=1,"ON","OFF") -> ON
B44: PM labor reduction (software) | C44: 0.45 | D44: =IF('Automation Costs'!C4=1,C44*(C17),0) -> 14040 | E44: =IF('Automation Costs'!C4=1,"ON","OFF") -> ON
...
